[2024-05-23T08:39:22.545+0000] {local_task_job_runner.py:120} INFO - ::group::Pre task execution logs
[2024-05-23T08:39:22.563+0000] {taskinstance.py:2076} INFO - Dependencies all met for dep_context=non-requeueable deps ti=<TaskInstance: Customer_Prosensity_DAG.insert_sqlite_from_csv manual__2024-05-23T08:39:12.767875+00:00 [queued]>
[2024-05-23T08:39:22.570+0000] {taskinstance.py:2076} INFO - Dependencies all met for dep_context=requeueable deps ti=<TaskInstance: Customer_Prosensity_DAG.insert_sqlite_from_csv manual__2024-05-23T08:39:12.767875+00:00 [queued]>
[2024-05-23T08:39:22.571+0000] {taskinstance.py:2306} INFO - Starting attempt 1 of 6
[2024-05-23T08:39:22.582+0000] {taskinstance.py:2330} INFO - Executing <Task(PythonOperator): insert_sqlite_from_csv> on 2024-05-23 08:39:12.767875+00:00
[2024-05-23T08:39:22.587+0000] {warnings.py:110} WARNING - /home/***/.local/lib/python3.12/site-packages/***/task/task_runner/standard_task_runner.py:61: DeprecationWarning: This process (pid=245) is multi-threaded, use of fork() may lead to deadlocks in the child.
  pid = os.fork()

[2024-05-23T08:39:22.589+0000] {standard_task_runner.py:63} INFO - Started process 247 to run task
[2024-05-23T08:39:22.589+0000] {standard_task_runner.py:90} INFO - Running: ['***', 'tasks', 'run', 'Customer_Prosensity_DAG', 'insert_sqlite_from_csv', 'manual__2024-05-23T08:39:12.767875+00:00', '--job-id', '4409', '--raw', '--subdir', 'DAGS_FOLDER/dag_with_customer_sqlite3.py', '--cfg-path', '/tmp/tmpztloo_dc']
[2024-05-23T08:39:22.590+0000] {standard_task_runner.py:91} INFO - Job 4409: Subtask insert_sqlite_from_csv
[2024-05-23T08:39:22.625+0000] {task_command.py:426} INFO - Running <TaskInstance: Customer_Prosensity_DAG.insert_sqlite_from_csv manual__2024-05-23T08:39:12.767875+00:00 [running]> on host cb453a136ab9
[2024-05-23T08:39:22.685+0000] {taskinstance.py:2648} INFO - Exporting env vars: AIRFLOW_CTX_DAG_OWNER='NhơnVõ' AIRFLOW_CTX_DAG_ID='Customer_Prosensity_DAG' AIRFLOW_CTX_TASK_ID='insert_sqlite_from_csv' AIRFLOW_CTX_EXECUTION_DATE='2024-05-23T08:39:12.767875+00:00' AIRFLOW_CTX_TRY_NUMBER='1' AIRFLOW_CTX_DAG_RUN_ID='manual__2024-05-23T08:39:12.767875+00:00'
[2024-05-23T08:39:22.687+0000] {taskinstance.py:430} INFO - ::endgroup::
[2024-05-23T08:39:25.910+0000] {taskinstance.py:441} INFO - ::group::Post task execution logs
[2024-05-23T08:39:25.911+0000] {taskinstance.py:2905} ERROR - Task failed with exception
Traceback (most recent call last):
  File "/home/airflow/.local/lib/python3.12/site-packages/sqlalchemy/engine/base.py", line 1890, in _execute_context
    self.dialect.do_executemany(
  File "/home/airflow/.local/lib/python3.12/site-packages/sqlalchemy/engine/default.py", line 733, in do_executemany
    cursor.executemany(statement, parameters)
sqlite3.OperationalError: table crud_simulation has no column named Unnamed: 0

The above exception was the direct cause of the following exception:

Traceback (most recent call last):
  File "/home/airflow/.local/lib/python3.12/site-packages/airflow/models/taskinstance.py", line 465, in _execute_task
    result = _execute_callable(context=context, **execute_callable_kwargs)
             ^^^^^^^^^^^^^^^^^^^^^^^^^^^^^^^^^^^^^^^^^^^^^^^^^^^^^^^^^^^^^
  File "/home/airflow/.local/lib/python3.12/site-packages/airflow/models/taskinstance.py", line 432, in _execute_callable
    return execute_callable(context=context, **execute_callable_kwargs)
           ^^^^^^^^^^^^^^^^^^^^^^^^^^^^^^^^^^^^^^^^^^^^^^^^^^^^^^^^^^^^
  File "/home/airflow/.local/lib/python3.12/site-packages/airflow/models/baseoperator.py", line 400, in wrapper
    return func(self, *args, **kwargs)
           ^^^^^^^^^^^^^^^^^^^^^^^^^^^
  File "/home/airflow/.local/lib/python3.12/site-packages/airflow/operators/python.py", line 235, in execute
    return_value = self.execute_callable()
                   ^^^^^^^^^^^^^^^^^^^^^^^
  File "/home/airflow/.local/lib/python3.12/site-packages/airflow/operators/python.py", line 252, in execute_callable
    return self.python_callable(*self.op_args, **self.op_kwargs)
           ^^^^^^^^^^^^^^^^^^^^^^^^^^^^^^^^^^^^^^^^^^^^^^^^^^^^^
  File "/opt/airflow/dags/dag_with_customer_sqlite3.py", line 25, in insert_sqlite_from_csv
    df.to_sql('crud_simulation', engine, if_exists='append', index=False)
  File "/home/airflow/.local/lib/python3.12/site-packages/pandas/util/_decorators.py", line 333, in wrapper
    return func(*args, **kwargs)
           ^^^^^^^^^^^^^^^^^^^^^
  File "/home/airflow/.local/lib/python3.12/site-packages/pandas/core/generic.py", line 3008, in to_sql
    return sql.to_sql(
           ^^^^^^^^^^^
  File "/home/airflow/.local/lib/python3.12/site-packages/pandas/io/sql.py", line 788, in to_sql
    return pandas_sql.to_sql(
           ^^^^^^^^^^^^^^^^^^
  File "/home/airflow/.local/lib/python3.12/site-packages/pandas/io/sql.py", line 1958, in to_sql
    total_inserted = sql_engine.insert_records(
                     ^^^^^^^^^^^^^^^^^^^^^^^^^^
  File "/home/airflow/.local/lib/python3.12/site-packages/pandas/io/sql.py", line 1507, in insert_records
    raise err
  File "/home/airflow/.local/lib/python3.12/site-packages/pandas/io/sql.py", line 1498, in insert_records
    return table.insert(chunksize=chunksize, method=method)
           ^^^^^^^^^^^^^^^^^^^^^^^^^^^^^^^^^^^^^^^^^^^^^^^^
  File "/home/airflow/.local/lib/python3.12/site-packages/pandas/io/sql.py", line 1059, in insert
    num_inserted = exec_insert(conn, keys, chunk_iter)
                   ^^^^^^^^^^^^^^^^^^^^^^^^^^^^^^^^^^^
  File "/home/airflow/.local/lib/python3.12/site-packages/pandas/io/sql.py", line 951, in _execute_insert
    result = conn.execute(self.table.insert(), data)
             ^^^^^^^^^^^^^^^^^^^^^^^^^^^^^^^^^^^^^^^
  File "/home/airflow/.local/lib/python3.12/site-packages/sqlalchemy/engine/base.py", line 1385, in execute
    return meth(self, multiparams, params, _EMPTY_EXECUTION_OPTS)
           ^^^^^^^^^^^^^^^^^^^^^^^^^^^^^^^^^^^^^^^^^^^^^^^^^^^^^^
  File "/home/airflow/.local/lib/python3.12/site-packages/sqlalchemy/sql/elements.py", line 334, in _execute_on_connection
    return connection._execute_clauseelement(
           ^^^^^^^^^^^^^^^^^^^^^^^^^^^^^^^^^^
  File "/home/airflow/.local/lib/python3.12/site-packages/sqlalchemy/engine/base.py", line 1577, in _execute_clauseelement
    ret = self._execute_context(
          ^^^^^^^^^^^^^^^^^^^^^^
  File "/home/airflow/.local/lib/python3.12/site-packages/sqlalchemy/engine/base.py", line 1953, in _execute_context
    self._handle_dbapi_exception(
  File "/home/airflow/.local/lib/python3.12/site-packages/sqlalchemy/engine/base.py", line 2134, in _handle_dbapi_exception
    util.raise_(
  File "/home/airflow/.local/lib/python3.12/site-packages/sqlalchemy/util/compat.py", line 211, in raise_
    raise exception
  File "/home/airflow/.local/lib/python3.12/site-packages/sqlalchemy/engine/base.py", line 1890, in _execute_context
    self.dialect.do_executemany(
  File "/home/airflow/.local/lib/python3.12/site-packages/sqlalchemy/engine/default.py", line 733, in do_executemany
    cursor.executemany(statement, parameters)
sqlalchemy.exc.OperationalError: (sqlite3.OperationalError) table crud_simulation has no column named Unnamed: 0
[SQL: INSERT INTO crud_simulation ("Unnamed: 0", user_id, basket_icon_click, basket_add_list, basket_add_detail, sort_by, image_picker, account_page_click, promo_banner_click, detail_wishlist_add, list_size_dropdown, closed_minibasket_click, checked_delivery_detail, checked_returns_detail, sign_in, saw_checkout, saw_sizecharts, saw_delivery, saw_account_upgrade, saw_homepage, device_computer, device_tablet, returning_user, loc_uk, propensity, score, created_at, updated_at) VALUES (?, ?, ?, ?, ?, ?, ?, ?, ?, ?, ?, ?, ?, ?, ?, ?, ?, ?, ?, ?, ?, ?, ?, ?, ?, ?, ?, ?)]
[parameters: ((0, '9d24-25k4-47889d24-25k4-494b-398124', 0, 0, 0, 0, 0, 0, 0, 0, 0, 0, 0, 0, 0, 0, 0, 0, 0, 0, 0, 0, 0, 1, 0.0, 6.9741490699595445, '2024-05-23 08:39:22.997894', '2024-05-23 08:39:22.998903'), (1, '7732-1k58-47887732-1k58-4475-679678', 0, 0, 0, 0, 0, 0, 0, 0, 0, 0, 0, 0, 0, 0, 0, 0, 0, 0, 0, 0, 0, 1, 0.0, 6.9741490699595445, '2024-05-23 08:39:22.997894', '2024-05-23 08:39:22.998903'), (2, '94k2-632j-471394k2-632j-4b4j-228160', 0, 0, 0, 0, 0, 0, 0, 0, 0, 0, 0, 0, 0, 0, 0, 0, 0, 0, 0, 0, 0, 1, 0.0, 6.9741490699595445, '2024-05-23 08:39:22.997894', '2024-05-23 08:39:22.998903'), (3, 'jdd8-419d-4714jdd8-419d-4198-674376', 0, 0, 1, 0, 0, 0, 0, 0, 0, 0, 0, 0, 0, 0, 0, 0, 0, 0, 0, 0, 0, 1, 0.0, 6.9741490699595445, '2024-05-23 08:39:22.997894', '2024-05-23 08:39:22.998903'), (4, '7473-7595-47147473-7595-4757-227547', 0, 0, 0, 0, 0, 0, 0, 0, 0, 0, 0, 0, 0, 0, 0, 0, 0, 0, 0, 0, 0, 1, 0.0, 6.9741490699595445, '2024-05-23 08:39:22.997894', '2024-05-23 08:39:22.998903'), (5, '7j3d-j382-47157j3d-j382-4d3b-955343', 1, 0, 1, 0, 0, 0, 0, 1, 1, 0, 1, 0, 1, 1, 0, 0, 0, 0, 0, 1, 1, 0, 1.0, 53.025850930040455, '2024-05-23 08:39:22.997894', '2024-05-23 08:39:22.998903'), (6, 'bb4d-8019-4715bb4d-8019-4d42-763898', 0, 0, 0, 0, 0, 0, 0, 0, 0, 0, 0, 0, 0, 0, 0, 0, 0, 0, 0, 1, 1, 1, 0.0, 6.9741490699595445, '2024-05-23 08:39:22.997894', '2024-05-23 08:39:22.998903'), (7, 'd09k-j446-4716d09k-j446-4469-572703', 0, 0, 0, 0, 0, 0, 0, 0, 0, 0, 0, 0, 0, 0, 0, 0, 0, 0, 0, 0, 1, 1, 0.0, 6.9741490699595445, '2024-05-23 08:39:22.997894', '2024-05-23 08:39:22.998903')  ... displaying 10 of 151655 total bound parameter sets ...  (151653, '5893-2228-0j165893-2228-4kb7-871348', 0, 0, 0, 0, 0, 0, 0, 0, 0, 0, 0, 0, 0, 0, 0, 0, 0, 0, 0, 0, 1, 1, 0.0, 6.9741490699595445, '2024-05-23 08:39:22.997894', '2024-05-23 08:39:22.998903'), (151654, '64k0-8720-0j1664k0-8720-447k-692331', 0, 0, 0, 0, 0, 0, 0, 0, 1, 0, 0, 0, 0, 0, 0, 0, 0, 1, 0, 1, 0, 1, 0.0, 6.9741490699595445, '2024-05-23 08:39:22.997894', '2024-05-23 08:39:22.998903'))]
(Background on this error at: https://sqlalche.me/e/14/e3q8)
[2024-05-23T08:39:25.923+0000] {taskinstance.py:1206} INFO - Marking task as UP_FOR_RETRY. dag_id=Customer_Prosensity_DAG, task_id=insert_sqlite_from_csv, run_id=manual__2024-05-23T08:39:12.767875+00:00, execution_date=20240523T083912, start_date=20240523T083922, end_date=20240523T083925
[2024-05-23T08:39:25.937+0000] {standard_task_runner.py:110} ERROR - Failed to execute job 4409 for task insert_sqlite_from_csv ((sqlite3.OperationalError) table crud_simulation has no column named Unnamed: 0
[SQL: INSERT INTO crud_simulation ("Unnamed: 0", user_id, basket_icon_click, basket_add_list, basket_add_detail, sort_by, image_picker, account_page_click, promo_banner_click, detail_wishlist_add, list_size_dropdown, closed_minibasket_click, checked_delivery_detail, checked_returns_detail, sign_in, saw_checkout, saw_sizecharts, saw_delivery, saw_account_upgrade, saw_homepage, device_computer, device_tablet, returning_user, loc_uk, propensity, score, created_at, updated_at) VALUES (?, ?, ?, ?, ?, ?, ?, ?, ?, ?, ?, ?, ?, ?, ?, ?, ?, ?, ?, ?, ?, ?, ?, ?, ?, ?, ?, ?)]
[parameters: ((0, '9d24-25k4-47889d24-25k4-494b-398124', 0, 0, 0, 0, 0, 0, 0, 0, 0, 0, 0, 0, 0, 0, 0, 0, 0, 0, 0, 0, 0, 1, 0.0, 6.9741490699595445, '2024-05-23 08:39:22.997894', '2024-05-23 08:39:22.998903'), (1, '7732-1k58-47887732-1k58-4475-679678', 0, 0, 0, 0, 0, 0, 0, 0, 0, 0, 0, 0, 0, 0, 0, 0, 0, 0, 0, 0, 0, 1, 0.0, 6.9741490699595445, '2024-05-23 08:39:22.997894', '2024-05-23 08:39:22.998903'), (2, '94k2-632j-471394k2-632j-4b4j-228160', 0, 0, 0, 0, 0, 0, 0, 0, 0, 0, 0, 0, 0, 0, 0, 0, 0, 0, 0, 0, 0, 1, 0.0, 6.9741490699595445, '2024-05-23 08:39:22.997894', '2024-05-23 08:39:22.998903'), (3, 'jdd8-419d-4714jdd8-419d-4198-674376', 0, 0, 1, 0, 0, 0, 0, 0, 0, 0, 0, 0, 0, 0, 0, 0, 0, 0, 0, 0, 0, 1, 0.0, 6.9741490699595445, '2024-05-23 08:39:22.997894', '2024-05-23 08:39:22.998903'), (4, '7473-7595-47147473-7595-4757-227547', 0, 0, 0, 0, 0, 0, 0, 0, 0, 0, 0, 0, 0, 0, 0, 0, 0, 0, 0, 0, 0, 1, 0.0, 6.9741490699595445, '2024-05-23 08:39:22.997894', '2024-05-23 08:39:22.998903'), (5, '7j3d-j382-47157j3d-j382-4d3b-955343', 1, 0, 1, 0, 0, 0, 0, 1, 1, 0, 1, 0, 1, 1, 0, 0, 0, 0, 0, 1, 1, 0, 1.0, 53.025850930040455, '2024-05-23 08:39:22.997894', '2024-05-23 08:39:22.998903'), (6, 'bb4d-8019-4715bb4d-8019-4d42-763898', 0, 0, 0, 0, 0, 0, 0, 0, 0, 0, 0, 0, 0, 0, 0, 0, 0, 0, 0, 1, 1, 1, 0.0, 6.9741490699595445, '2024-05-23 08:39:22.997894', '2024-05-23 08:39:22.998903'), (7, 'd09k-j446-4716d09k-j446-4469-572703', 0, 0, 0, 0, 0, 0, 0, 0, 0, 0, 0, 0, 0, 0, 0, 0, 0, 0, 0, 0, 1, 1, 0.0, 6.9741490699595445, '2024-05-23 08:39:22.997894', '2024-05-23 08:39:22.998903')  ... displaying 10 of 151655 total bound parameter sets ...  (151653, '5893-2228-0j165893-2228-4kb7-871348', 0, 0, 0, 0, 0, 0, 0, 0, 0, 0, 0, 0, 0, 0, 0, 0, 0, 0, 0, 0, 1, 1, 0.0, 6.9741490699595445, '2024-05-23 08:39:22.997894', '2024-05-23 08:39:22.998903'), (151654, '64k0-8720-0j1664k0-8720-447k-692331', 0, 0, 0, 0, 0, 0, 0, 0, 1, 0, 0, 0, 0, 0, 0, 0, 0, 1, 0, 1, 0, 1, 0.0, 6.9741490699595445, '2024-05-23 08:39:22.997894', '2024-05-23 08:39:22.998903'))]
(Background on this error at: https://sqlalche.me/e/14/e3q8); 247)
[2024-05-23T08:39:25.975+0000] {local_task_job_runner.py:240} INFO - Task exited with return code 1
[2024-05-23T08:39:25.991+0000] {taskinstance.py:3498} INFO - 0 downstream tasks scheduled from follow-on schedule check
[2024-05-23T08:39:25.993+0000] {local_task_job_runner.py:222} INFO - ::endgroup::
